Traceback (most recent call last):
  File "/grad/1/ktjoseph/nlpclass-1197-g-skh/hw2/venv/lib/python3.5/site-packages/pymagnitude/__init__.py", line 2154, in download_model
    os.path.join(download_dir, local_file_name_tmp)
  File "/usr/lib/python3.5/urllib/request.py", line 188, in urlretrieve
    with contextlib.closing(urlopen(url, data)) as fp:
  File "/usr/lib/python3.5/urllib/request.py", line 163, in urlopen
    return opener.open(url, data, timeout)
  File "/usr/lib/python3.5/urllib/request.py", line 472, in open
    response = meth(req, response)
  File "/usr/lib/python3.5/urllib/request.py", line 582, in http_response
    'http', request, response, code, msg, hdrs)
  File "/usr/lib/python3.5/urllib/request.py", line 510, in error
    return self._call_chain(*args)
  File "/usr/lib/python3.5/urllib/request.py", line 444, in _call_chain
    result = func(*args)
  File "/usr/lib/python3.5/urllib/request.py", line 590, in http_error_default
    raise HTTPError(req.full_url, code, msg, hdrs, fp)
urllib.error.HTTPError: HTTP Error 400: Invalid URI

During handling of the above exception, another exception occurred:

Traceback (most recent call last):
  File "/grad/1/ktjoseph/nlpclass-1197-g-skh/hw2/answer/lexsub.py", line 26, in <module>
    lexsub = LexSub(opts.wordvecfile, int(opts.topn))
  File "/grad/1/ktjoseph/nlpclass-1197-g-skh/hw2/answer/lexsub.py", line 8, in __init__
    self.wvecs = pymagnitude.Magnitude(wvec_file)
  File "/grad/1/ktjoseph/nlpclass-1197-g-skh/hw2/venv/lib/python3.5/site-packages/pymagnitude/__init__.py", line 352, in __init__
    self.path, log=self.log, _local=True)
  File "/grad/1/ktjoseph/nlpclass-1197-g-skh/hw2/venv/lib/python3.5/site-packages/pymagnitude/__init__.py", line 2173, in download_model
    remote_file_path)
RuntimeError: The path to the Magnitude file at '../wordVecs/data/glove.6B.100d.magnitude' could not be found. Also failed to find a valid remote model at the following URL: http://magnitude.plasticity.ai/../wordVecs/data/glove.6B.100d.magnitude
